Workbook

Sheet 使用說明
A1: 三策開發評估系統｜清冊匯入標準模板 v7
A2: 三策專案管理顧問有限公司
A3: Sanze Project Management Consulting Co., Ltd.
A4: 本模板為三策開發評估系統授權使用之標準清冊匯入格式。未經授權不得修改欄位結構、公式、驗證規則或轉作其他用途。
A6: 使用方式 | B6: 請由清冊產生器或三策系統匯出本檔。匯入前請確認必填欄位與公式檢核提示。
A7: 資料列 | B7: 各匯入 sheet 第 5 列為欄位名稱，第 6 列起為資料列。
A8: 公式欄 | B8: 灰底欄位為公式或系統輔助欄，請勿手動覆寫。
A9: 保護 | B9: 本檔於資料、格式、公式寫入完成後才套用 sheet protection；可輸入欄位保持 unlocked。
A10: 注意 | B10: 低信心、人工確認或來源不完整資料不可直接作正式資料。

Sheet 土地清冊_匯入
A1: 三策專案管理顧問有限公司
A2: Sanze Project Management Consulting Co., Ltd.
A3: 本模板為三策開發評估系統授權使用之標準清冊匯入格式。未經授權不得修改欄位結構、公式、驗證規則或轉作其他用途。
A4: 必填 | B4: 必填 | C4: 必填 | D4: 必填 | E4: 必填 | F4: 選填 | G4: 必填 | H4: 必填 | I4: 公式 | J4: 必填 | K4: 必填 | L4: 公式 | M4: 公式 | N4: 建議 | O4: 選填 | P4: 選填 | Q4: 建議 | R4: 建議 | S4: 建議 | T4: 選填 | U4: 建議 | V4: 建議 | W4: 建議 | X4: 選填 | Y4: 建議 | Z4: 選填 | AA4: 公式 | AB4: 公式
A5: 地主編號 | B5: 地主姓名 | C5: 縣市 | D5: 行政區 | E5: 段別 | F5: 小段 | G5: 地號 | H5: 土地面積㎡ | I5: 土地面積坪 | J5: 持分分子 | K5: 持分分母 | L5: 持分比例 | M5: 持分面積坪 | N5: 使用分區 | O5: 公告現值（元/㎡） | P5: 公告地價 | Q5: 抵押設定 | R5: 查封限制 | S5: 繼承狀態 | T5: 聯絡方式 | U5: 聯絡狀態 | V5: 同意狀態 | W5: 簽約狀態 | X5: 整合負責人 | Y5: 風險等級 | Z5: 特殊備註 | AA5: 公式檢核提示 | AB5: 地主地號查找鍵
I6: =IF(H6="","",ROUND(H6/3.305785,3)) | L6: =IF(OR(J6="",K6="",K6=0),"",ROUND(J6/K6,6)) | M6: =IF(OR(H6="",J6="",K6="",K6=0),"",ROUND(H6*J6/K6/3.305785,3)) | AA6: =IF(A6="","",IF(OR(B6="",C6="",D6="",E6="",G6="",H6="",J6="",K6=""),"必填欄位未完整","")) | AB6: =IF(A6="","",A6&"|"&G6)
I7: =IF(H7="","",ROUND(H7/3.305785,3)) | L7: =IF(OR(J7="",K7="",K7=0),"",ROUND(J7/K7,6)) | M7: =IF(OR(H7="",J7="",K7="",K7=0),"",ROUND(H7*J7/K7/3.305785,3)) | AA7: =IF(A7="","",IF(OR(B7="",C7="",D7="",E7="",G7="",H7="",J7="",K7=""),"必填欄位未完整","")) | AB7: =IF(A7="","",A7&"|"&G7)
I8: =IF(H8="","",ROUND(H8/3.305785,3)) | L8: =IF(OR(J8="",K8="",K8=0),"",ROUND(J8/K8,6)) | M8: =IF(OR(H8="",J8="",K8="",K8=0),"",ROUND(H8*J8/K8/3.305785,3)) | AA8: =IF(A8="","",IF(OR(B8="",C8="",D8="",E8="",G8="",H8="",J8="",K8=""),"必填欄位未完整","")) | AB8: =IF(A8="","",A8&"|"&G8)
I9: =IF(H9="","",ROUND(H9/3.305785,3)) | L9: =IF(OR(J9="",K9="",K9=0),"",ROUND(J9/K9,6)) | M9: =IF(OR(H9="",J9="",K9="",K9=0),"",ROUND(H9*J9/K9/3.305785,3)) | AA9: =IF(A9="","",IF(OR(B9="",C9="",D9="",E9="",G9="",H9="",J9="",K9=""),"必填欄位未完整","")) | AB9: =IF(A9="","",A9&"|"&G9)
I10: =IF(H10="","",ROUND(H10/3.305785,3)) | L10: =IF(OR(J10="",K10="",K10=0),"",ROUND(J10/K10,6)) | M10: =IF(OR(H10="",J10="",K10="",K10=0),"",ROUND(H10*J10/K10/3.305785,3)) | AA10: =IF(A10="","",IF(OR(B10="",C10="",D10="",E10="",G10="",H10="",J10="",K10=""),"必填欄位未完整","")) | AB10: =IF(A10="","",A10&"|"&G10)
I11: =IF(H11="","",ROUND(H11/3.305785,3)) | L11: =IF(OR(J11="",K11="",K11=0),"",ROUND(J11/K11,6)) | M11: =IF(OR(H11="",J11="",K11="",K11=0),"",ROUND(H11*J11/K11/3.305785,3)) | AA11: =IF(A11="","",IF(OR(B11="",C11="",D11="",E11="",G11="",H11="",J11="",K11=""),"必填欄位未完整","")) | AB11: =IF(A11="","",A11&"|"&G11)
I12: =IF(H12="","",ROUND(H12/3.305785,3)) | L12: =IF(OR(J12="",K12="",K12=0),"",ROUND(J12/K12,6)) | M12: =IF(OR(H12="",J12="",K12="",K12=0),"",ROUND(H12*J12/K12/3.305785,3)) | AA12: =IF(A12="","",IF(OR(B12="",C12="",D12="",E12="",G12="",H12="",J12="",K12=""),"必填欄位未完整","")) | AB12: =IF(A12="","",A12&"|"&G12)
I13: =IF(H13="","",ROUND(H13/3.305785,3)) | L13: =IF(OR(J13="",K13="",K13=0),"",ROUND(J13/K13,6)) | M13: =IF(OR(H13="",J13="",K13="",K13=0),"",ROUND(H13*J13/K13/3.305785,3)) | AA13: =IF(A13="","",IF(OR(B13="",C13="",D13="",E13="",G13="",H13="",J13="",K13=""),"必填欄位未完整","")) | AB13: =IF(A13="","",A13&"|"&G13)
I14: =IF(H14="","",ROUND(H14/3.305785,3)) | L14: =IF(OR(J14="",K14="",K14=0),"",ROUND(J14/K14,6)) | M14: =IF(OR(H14="",J14="",K14="",K14=0),"",ROUND(H14*J14/K14/3.305785,3)) | AA14: =IF(A14="","",IF(OR(B14="",C14="",D14="",E14="",G14="",H14="",J14="",K14=""),"必填欄位未完整","")) | AB14: =IF(A14="","",A14&"|"&G14)
I15: =IF(H15="","",ROUND(H15/3.305785,3)) | L15: =IF(OR(J15="",K15="",K15=0),"",ROUND(J15/K15,6)) | M15: =IF(OR(H15="",J15="",K15="",K15=0),"",ROUND(H15*J15/K15/3.305785,3)) | AA15: =IF(A15="","",IF(OR(B15="",C15="",D15="",E15="",G15="",H15="",J15="",K15=""),"必填欄位未完整","")) | AB15: =IF(A15="","",A15&"|"&G15)
I16: =IF(H16="","",ROUND(H16/3.305785,3)) | L16: =IF(OR(J16="",K16="",K16=0),"",ROUND(J16/K16,6)) | M16: =IF(OR(H16="",J16="",K16="",K16=0),"",ROUND(H16*J16/K16/3.305785,3)) | AA16: =IF(A16="","",IF(OR(B16="",C16="",D16="",E16="",G16="",H16="",J16="",K16=""),"必填欄位未完整","")) | AB16: =IF(A16="","",A16&"|"&G16)
I17: =IF(H17="","",ROUND(H17/3.305785,3)) | L17: =IF(OR(J17="",K17="",K17=0),"",ROUND(J17/K17,6)) | M17: =IF(OR(H17="",J17="",K17="",K17=0),"",ROUND(H17*J17/K17/3.305785,3)) | AA17: =IF(A17="","",IF(OR(B17="",C17="",D17="",E17="",G17="",H17="",J17="",K17=""),"必填欄位未完整","")) | AB17: =IF(A17="","",A17&"|"&G17)
... I1005: =IF(H1005="","",ROUND(H1005/3.305785,3)) | L1005: =IF(OR(J1005="",K1005="",K1005=0),"",ROUND(J1005/K1005,6)) | M1005: =IF(OR(H1005="",J1005="",K1005="",K1005=0),"",ROUND(H1005*J1005/K1005/3.305785,3)) | AA1005: =IF(A1005="","",IF(OR(B1005="",C1005="",D1005="",E1005="",G1005="",H1005="",J1005="",K1005=""),"必填欄位未完整","")) | AB1005: =IF(A1005="","",A1005&"|"&G1005)

Sheet 建物清冊_匯入
A1: 三策專案管理顧問有限公司
A2: Sanze Project Management Consulting Co., Ltd.
A3: 本模板為三策開發評估系統授權使用之標準清冊匯入格式。未經授權不得修改欄位結構、公式、驗證規則或轉作其他用途。
A4: 必填 | B4: 必填 | C4: 必填 | D4: 必填 | E4: 必填 | F4: 選填 | G4: 建議 | H4: 必填 | I4: 選填 | J4: 建議 | K4: 建議 | L4: 建議 | M4: 選填 | N4: 選填 | O4: 必填 | P4: 選填 | Q4: 選填 | R4: 公式 | S4: 公式 | T4: 必填 | U4: 必填 | V4: 公式 | W4: 公式 | X4: 選填 | Y4: 建議 | Z4: 建議 | AA4: 選填 | AB4: 建議 | AC4: 建議 | AD4: 建議 | AE4: 建議 | AF4: 建議 | AG4: 選填 | AH4: 公式 | AI4: 公式 | AJ4: 公式
A5: 建物編號 | B5: 所有人姓名 | C5: 縣市 | D5: 行政區 | E5: 段別 | F5: 小段 | G5: 地號 | H5: 建號 | I5: 聯絡方式 | J5: 聯絡狀態 | K5: 同意狀態 | L5: 簽約狀態 | M5: 整合負責人 | N5: 特殊備註 | O5: 主建物面積㎡ | P5: 附屬建物面積㎡ | Q5: 共有部分面積㎡ | R5: 建物面積㎡ | S5: 建物面積坪 | T5: 持分分子 | U5: 持分分母 | V5: 持分比例 | W5: 建物持分面積㎡ | X5: 樓層 | Y5: 建物型態 | Z5: 用途 | AA5: 屋齡 | AB5: 是否出租 | AC5: 是否抵押 | AD5: 是否占用 | AE5: 是否違建 | AF5: 風險等級 | AG5: 建物備註 | AH5: 公式檢核提示 | AI5: 地主地號查找鍵 | AJ5: 地主建號查找鍵
R6: =IF(O6="","",SUM(O6:Q6)) | S6: =IF(R6="","",ROUND(R6/3.305785,3)) | V6: =IF(OR(T6="",U6="",U6=0),"",ROUND(T6/U6,6)) | W6: =IF(OR(R6="",T6="",U6="",U6=0),"",ROUND(R6*T6/U6,3)) | AH6: =IF(A6="","",IF(OR(B6="",C6="",D6="",E6="",H6="",O6="",T6="",U6=""),"必填欄位未完整","")) | AI6: =IF(A6="","",A6&"|"&G6) | AJ6: =IF(A6="","",A6&"|"&H6)
R7: =IF(O7="","",SUM(O7:Q7)) | S7: =IF(R7="","",ROUND(R7/3.305785,3)) | V7: =IF(OR(T7="",U7="",U7=0),"",ROUND(T7/U7,6)) | W7: =IF(OR(R7="",T7="",U7="",U7=0),"",ROUND(R7*T7/U7,3)) | AH7: =IF(A7="","",IF(OR(B7="",C7="",D7="",E7="",H7="",O7="",T7="",U7=""),"必填欄位未完整","")) | AI7: =IF(A7="","",A7&"|"&G7) | AJ7: =IF(A7="","",A7&"|"&H7)
R8: =IF(O8="","",SUM(O8:Q8)) | S8: =IF(R8="","",ROUND(R8/3.305785,3)) | V8: =IF(OR(T8="",U8="",U8=0),"",ROUND(T8/U8,6)) | W8: =IF(OR(R8="",T8="",U8="",U8=0),"",ROUND(R8*T8/U8,3)) | AH8: =IF(A8="","",IF(OR(B8="",C8="",D8="",E8="",H8="",O8="",T8="",U8=""),"必填欄位未完整","")) | AI8: =IF(A8="","",A8&"|"&G8) | AJ8: =IF(A8="","",A8&"|"&H8)
R9: =IF(O9="","",SUM(O9:Q9)) | S9: =IF(R9="","",ROUND(R9/3.305785,3)) | V9: =IF(OR(T9="",U9="",U9=0),"",ROUND(T9/U9,6)) | W9: =IF(OR(R9="",T9="",U9="",U9=0),"",ROUND(R9*T9/U9,3)) | AH9: =IF(A9="","",IF(OR(B9="",C9="",D9="",E9="",H9="",O9="",T9="",U9=""),"必填欄位未完整","")) | AI9: =IF(A9="","",A9&"|"&G9) | AJ9: =IF(A9="","",A9&"|"&H9)
R10: =IF(O10="","",SUM(O10:Q10)) | S10: =IF(R10="","",ROUND(R10/3.305785,3)) | V10: =IF(OR(T10="",U10="",U10=0),"",ROUND(T10/U10,6)) | W10: =IF(OR(R10="",T10="",U10="",U10=0),"",ROUND(R10*T10/U10,3)) | AH10: =IF(A10="","",IF(OR(B10="",C10="",D10="",E10="",H10="",O10="",T10="",U10=""),"必填欄位未完整","")) | AI10: =IF(A10="","",A10&"|"&G10) | AJ10: =IF(A10="","",A10&"|"&H10)
R11: =IF(O11="","",SUM(O11:Q11)) | S11: =IF(R11="","",ROUND(R11/3.305785,3)) | V11: =IF(OR(T11="",U11="",U11=0),"",ROUND(T11/U11,6)) | W11: =IF(OR(R11="",T11="",U11="",U11=0),"",ROUND(R11*T11/U11,3)) | AH11: =IF(A11="","",IF(OR(B11="",C11="",D11="",E11="",H11="",O11="",T11="",U11=""),"必填欄位未完整","")) | AI11: =IF(A11="","",A11&"|"&G11) | AJ11: =IF(A11="","",A11&"|"&H11)
R12: =IF(O12="","",SUM(O12:Q12)) | S12: =IF(R12="","",ROUND(R12/3.305785,3)) | V12: =IF(OR(T12="",U12="",U12=0),"",ROUND(T12/U12,6)) | W12: =IF(OR(R12="",T12="",U12="",U12=0),"",ROUND(R12*T12/U12,3)) | AH12: =IF(A12="","",IF(OR(B12="",C12="",D12="",E12="",H12="",O12="",T12="",U12=""),"必填欄位未完整","")) | AI12: =IF(A12="","",A12&"|"&G12) | AJ12: =IF(A12="","",A12&"|"&H12)
R13: =IF(O13="","",SUM(O13:Q13)) | S13: =IF(R13="","",ROUND(R13/3.305785,3)) | V13: =IF(OR(T13="",U13="",U13=0),"",ROUND(T13/U13,6)) | W13: =IF(OR(R13="",T13="",U13="",U13=0),"",ROUND(R13*T13/U13,3)) | AH13: =IF(A13="","",IF(OR(B13="",C13="",D13="",E13="",H13="",O13="",T13="",U13=""),"必填欄位未完整","")) | AI13: =IF(A13="","",A13&"|"&G13) | AJ13: =IF(A13="","",A13&"|"&H13)
R14: =IF(O14="","",SUM(O14:Q14)) | S14: =IF(R14="","",ROUND(R14/3.305785,3)) | V14: =IF(OR(T14="",U14="",U14=0),"",ROUND(T14/U14,6)) | W14: =IF(OR(R14="",T14="",U14="",U14=0),"",ROUND(R14*T14/U14,3)) | AH14: =IF(A14="","",IF(OR(B14="",C14="",D14="",E14="",H14="",O14="",T14="",U14=""),"必填欄位未完整","")) | AI14: =IF(A14="","",A14&"|"&G14) | AJ14: =IF(A14="","",A14&"|"&H14)
R15: =IF(O15="","",SUM(O15:Q15)) | S15: =IF(R15="","",ROUND(R15/3.305785,3)) | V15: =IF(OR(T15="",U15="",U15=0),"",ROUND(T15/U15,6)) | W15: =IF(OR(R15="",T15="",U15="",U15=0),"",ROUND(R15*T15/U15,3)) | AH15: =IF(A15="","",IF(OR(B15="",C15="",D15="",E15="",H15="",O15="",T15="",U15=""),"必填欄位未完整","")) | AI15: =IF(A15="","",A15&"|"&G15) | AJ15: =IF(A15="","",A15&"|"&H15)
R16: =IF(O16="","",SUM(O16:Q16)) | S16: =IF(R16="","",ROUND(R16/3.305785,3)) | V16: =IF(OR(T16="",U16="",U16=0),"",ROUND(T16/U16,6)) | W16: =IF(OR(R16="",T16="",U16="",U16=0),"",ROUND(R16*T16/U16,3)) | AH16: =IF(A16="","",IF(OR(B16="",C16="",D16="",E16="",H16="",O16="",T16="",U16=""),"必填欄位未完整","")) | AI16: =IF(A16="","",A16&"|"&G16) | AJ16: =IF(A16="","",A16&"|"&H16)
R17: =IF(O17="","",SUM(O17:Q17)) | S17: =IF(R17="","",ROUND(R17/3.305785,3)) | V17: =IF(OR(T17="",U17="",U17=0),"",ROUND(T17/U17,6)) | W17: =IF(OR(R17="",T17="",U17="",U17=0),"",ROUND(R17*T17/U17,3)) | AH17: =IF(A17="","",IF(OR(B17="",C17="",D17="",E17="",H17="",O17="",T17="",U17=""),"必填欄位未完整","")) | AI17: =IF(A17="","",A17&"|"&G17) | AJ17: =IF(A17="","",A17&"|"&H17)
... R1005: =IF(O1005="","",SUM(O1005:Q1005)) | S1005: =IF(R1005="","",ROUND(R1005/3.305785,3)) | V1005: =IF(OR(T1005="",U1005="",U1005=0),"",ROUND(T1005/U1005,6)) | W1005: =IF(OR(R1005="",T1005="",U1005="",U1005=0),"",ROUND(R1005*T1005/U1005,3)) | AH1005: =IF(A1005="","",IF(OR(B1005="",C1005="",D1005="",E1005="",H1005="",O1005="",T1005="",U1005=""),"必填欄位未完整","")) | AI1005: =IF(A1005="","",A1005&"|"&G1005) | AJ1005: =IF(A1005="","",A1005&"|"&H1005)

Sheet 整合紀錄_匯入
A1: 三策專案管理顧問有限公司
A2: Sanze Project Management Consulting Co., Ltd.
A3: 本模板為三策開發評估系統授權使用之標準清冊匯入格式。未經授權不得修改欄位結構、公式、驗證規則或轉作其他用途。
A4: 必填 | B4: 建議 | C4: 公式 | D4: 公式 | E4: 公式 | F4: 公式 | G4: 公式 | H4: 公式 | I4: 公式 | J4: 建議 | K4: 建議 | L4: 建議 | M4: 建議 | N4: 建議 | O4: 建議 | P4: 建議 | Q4: 選填 | R4: 選填 | S4: 選填 | T4: 選填 | U4: 公式
A5: 地主編號 | B5: 對應地號 | C5: 地主姓名 | D5: 聯絡方式 | E5: 目前聯絡狀態 | F5: 目前同意狀態 | G5: 目前簽約狀態 | H5: 整合負責人 | I5: 特殊備註 | J5: 聯絡日期 | K5: 本次聯絡方式 | L5: 聯絡結果 | M5: 本次同意狀態 | N5: 本次簽約狀態 | O5: 風險等級 | P5: 下一步處理 | Q5: 下次追蹤日期 | R5: 溝通摘要 | S5: 待補資料 | T5: 備註 | U5: 提示
C6: =IF($A6="","",IFERROR(INDEX(土地清冊_匯入!$B$6:$B$1005,MATCH($A6,土地清冊_匯入!$A$6:$A$1005,0)),"查無資料")) | D6: =IF($A6="","",IFERROR(INDEX(土地清冊_匯入!$P$6:$P$1005,MATCH($A6,土地清冊_匯入!$A$6:$A$1005,0)),"")) | E6: =IF($A6="","",IFERROR(INDEX(土地清冊_匯入!$Q$6:$Q$1005,MATCH($A6,土地清冊_匯入!$A$6:$A$1005,0)),"")) | F6: =IF($A6="","",IFERROR(INDEX(土地清冊_匯入!$R$6:$R$1005,MATCH($A6,土地清冊_匯入!$A$6:$A$1005,0)),"")) | G6: =IF($A6="","",IFERROR(INDEX(土地清冊_匯入!$S$6:$S$1005,MATCH($A6,土地清冊_匯入!$A$6:$A$1005,0)),"")) | H6: =IF($A6="","",IFERROR(INDEX(土地清冊_匯入!$T$6:$T$1005,MATCH($A6,土地清冊_匯入!$A$6:$A$1005,0)),"")) | I6: =IF($A6="","",IFERROR(INDEX(土地清冊_匯入!$V$6:$V$1005,MATCH($A6,土地清冊_匯入!$A$6:$A$1005,0)),"")) | U6: =IF(A6="","",IF(OR(J6="",L6=""),"建議補聯絡紀錄","") )
C7: =IF($A7="","",IFERROR(INDEX(土地清冊_匯入!$B$6:$B$1005,MATCH($A7,土地清冊_匯入!$A$6:$A$1005,0)),"查無資料")) | D7: =IF($A7="","",IFERROR(INDEX(土地清冊_匯入!$P$6:$P$1005,MATCH($A7,土地清冊_匯入!$A$6:$A$1005,0)),"")) | E7: =IF($A7="","",IFERROR(INDEX(土地清冊_匯入!$Q$6:$Q$1005,MATCH($A7,土地清冊_匯入!$A$6:$A$1005,0)),"")) | F7: =IF($A7="","",IFERROR(INDEX(土地清冊_匯入!$R$6:$R$1005,MATCH($A7,土地清冊_匯入!$A$6:$A$1005,0)),"")) | G7: =IF($A7="","",IFERROR(INDEX(土地清冊_匯入!$S$6:$S$1005,MATCH($A7,土地清冊_匯入!$A$6:$A$1005,0)),"")) | H7: =IF($A7="","",IFERROR(INDEX(土地清冊_匯入!$T$6:$T$1005,MATCH($A7,土地清冊_匯入!$A$6:$A$1005,0)),"")) | I7: =IF($A7="","",IFERROR(INDEX(土地清冊_匯入!$V$6:$V$1005,MATCH($A7,土地清冊_匯入!$A$6:$A$1005,0)),"")) | U7: =IF(A7="","",IF(OR(J7="",L7=""),"建議補聯絡紀錄","") )
C8: =IF($A8="","",IFERROR(INDEX(土地清冊_匯入!$B$6:$B$1005,MATCH($A8,土地清冊_匯入!$A$6:$A$1005,0)),"查無資料")) | D8: =IF($A8="","",IFERROR(INDEX(土地清冊_匯入!$P$6:$P$1005,MATCH($A8,土地清冊_匯入!$A$6:$A$1005,0)),"")) | E8: =IF($A8="","",IFERROR(INDEX(土地清冊_匯入!$Q$6:$Q$1005,MATCH($A8,土地清冊_匯入!$A$6:$A$1005,0)),"")) | F8: =IF($A8="","",IFERROR(INDEX(土地清冊_匯入!$R$6:$R$1005,MATCH($A8,土地清冊_匯入!$A$6:$A$1005,0)),"")) | G8: =IF($A8="","",IFERROR(INDEX(土地清冊_匯入!$S$6:$S$1005,MATCH($A8,土地清冊_匯入!$A$6:$A$1005,0)),"")) | H8: =IF($A8="","",IFERROR(INDEX(土地清冊_匯入!$T$6:$T$1005,MATCH($A8,土地清冊_匯入!$A$6:$A$1005,0)),"")) | I8: =IF($A8="","",IFERROR(INDEX(土地清冊_匯入!$V$6:$V$1005,MATCH($A8,土地清冊_匯入!$A$6:$A$1005,0)),"")) | U8: =IF(A8="","",IF(OR(J8="",L8=""),"建議補聯絡紀錄","") )
C9: =IF($A9="","",IFERROR(INDEX(土地清冊_匯入!$B$6:$B$1005,MATCH($A9,土地清冊_匯入!$A$6:$A$1005,0)),"查無資料")) | D9: =IF($A9="","",IFERROR(INDEX(土地清冊_匯入!$P$6:$P$1005,MATCH($A9,土地清冊_匯入!$A$6:$A$1005,0)),"")) | E9: =IF($A9="","",IFERROR(INDEX(土地清冊_匯入!$Q$6:$Q$1005,MATCH($A9,土地清冊_匯入!$A$6:$A$1005,0)),"")) | F9: =IF($A9="","",IFERROR(INDEX(土地清冊_匯入!$R$6:$R$1005,MATCH($A9,土地清冊_匯入!$A$6:$A$1005,0)),"")) | G9: =IF($A9="","",IFERROR(INDEX(土地清冊_匯入!$S$6:$S$1005,MATCH($A9,土地清冊_匯入!$A$6:$A$1005,0)),"")) | H9: =IF($A9="","",IFERROR(INDEX(土地清冊_匯入!$T$6:$T$1005,MATCH($A9,土地清冊_匯入!$A$6:$A$1005,0)),"")) | I9: =IF($A9="","",IFERROR(INDEX(土地清冊_匯入!$V$6:$V$1005,MATCH($A9,土地清冊_匯入!$A$6:$A$1005,0)),"")) | U9: =IF(A9="","",IF(OR(J9="",L9=""),"建議補聯絡紀錄","") )
C10: =IF($A10="","",IFERROR(INDEX(土地清冊_匯入!$B$6:$B$1005,MATCH($A10,土地清冊_匯入!$A$6:$A$1005,0)),"查無資料")) | D10: =IF($A10="","",IFERROR(INDEX(土地清冊_匯入!$P$6:$P$1005,MATCH($A10,土地清冊_匯入!$A$6:$A$1005,0)),"")) | E10: =IF($A10="","",IFERROR(INDEX(土地清冊_匯入!$Q$6:$Q$1005,MATCH($A10,土地清冊_匯入!$A$6:$A$1005,0)),"")) | F10: =IF($A10="","",IFERROR(INDEX(土地清冊_匯入!$R$6:$R$1005,MATCH($A10,土地清冊_匯入!$A$6:$A$1005,0)),"")) | G10: =IF($A10="","",IFERROR(INDEX(土地清冊_匯入!$S$6:$S$1005,MATCH($A10,土地清冊_匯入!$A$6:$A$1005,0)),"")) | H10: =IF($A10="","",IFERROR(INDEX(土地清冊_匯入!$T$6:$T$1005,MATCH($A10,土地清冊_匯入!$A$6:$A$1005,0)),"")) | I10: =IF($A10="","",IFERROR(INDEX(土地清冊_匯入!$V$6:$V$1005,MATCH($A10,土地清冊_匯入!$A$6:$A$1005,0)),"")) | U10: =IF(A10="","",IF(OR(J10="",L10=""),"建議補聯絡紀錄","") )
C11: =IF($A11="","",IFERROR(INDEX(土地清冊_匯入!$B$6:$B$1005,MATCH($A11,土地清冊_匯入!$A$6:$A$1005,0)),"查無資料")) | D11: =IF($A11="","",IFERROR(INDEX(土地清冊_匯入!$P$6:$P$1005,MATCH($A11,土地清冊_匯入!$A$6:$A$1005,0)),"")) | E11: =IF($A11="","",IFERROR(INDEX(土地清冊_匯入!$Q$6:$Q$1005,MATCH($A11,土地清冊_匯入!$A$6:$A$1005,0)),"")) | F11: =IF($A11="","",IFERROR(INDEX(土地清冊_匯入!$R$6:$R$1005,MATCH($A11,土地清冊_匯入!$A$6:$A$1005,0)),"")) | G11: =IF($A11="","",IFERROR(INDEX(土地清冊_匯入!$S$6:$S$1005,MATCH($A11,土地清冊_匯入!$A$6:$A$1005,0)),"")) | H11: =IF($A11="","",IFERROR(INDEX(土地清冊_匯入!$T$6:$T$1005,MATCH($A11,土地清冊_匯入!$A$6:$A$1005,0)),"")) | I11: =IF($A11="","",IFERROR(INDEX(土地清冊_匯入!$V$6:$V$1005,MATCH($A11,土地清冊_匯入!$A$6:$A$1005,0)),"")) | U11: =IF(A11="","",IF(OR(J11="",L11=""),"建議補聯絡紀錄","") )
C12: =IF($A12="","",IFERROR(INDEX(土地清冊_匯入!$B$6:$B$1005,MATCH($A12,土地清冊_匯入!$A$6:$A$1005,0)),"查無資料")) | D12: =IF($A12="","",IFERROR(INDEX(土地清冊_匯入!$P$6:$P$1005,MATCH($A12,土地清冊_匯入!$A$6:$A$1005,0)),"")) | E12: =IF($A12="","",IFERROR(INDEX(土地清冊_匯入!$Q$6:$Q$1005,MATCH($A12,土地清冊_匯入!$A$6:$A$1005,0)),"")) | F12: =IF($A12="","",IFERROR(INDEX(土地清冊_匯入!$R$6:$R$1005,MATCH($A12,土地清冊_匯入!$A$6:$A$1005,0)),"")) | G12: =IF($A12="","",IFERROR(INDEX(土地清冊_匯入!$S$6:$S$1005,MATCH($A12,土地清冊_匯入!$A$6:$A$1005,0)),"")) | H12: =IF($A12="","",IFERROR(INDEX(土地清冊_匯入!$T$6:$T$1005,MATCH($A12,土地清冊_匯入!$A$6:$A$1005,0)),"")) | I12: =IF($A12="","",IFERROR(INDEX(土地清冊_匯入!$V$6:$V$1005,MATCH($A12,土地清冊_匯入!$A$6:$A$1005,0)),"")) | U12: =IF(A12="","",IF(OR(J12="",L12=""),"建議補聯絡紀錄","") )
C13: =IF($A13="","",IFERROR(INDEX(土地清冊_匯入!$B$6:$B$1005,MATCH($A13,土地清冊_匯入!$A$6:$A$1005,0)),"查無資料")) | D13: =IF($A13="","",IFERROR(INDEX(土地清冊_匯入!$P$6:$P$1005,MATCH($A13,土地清冊_匯入!$A$6:$A$1005,0)),"")) | E13: =IF($A13="","",IFERROR(INDEX(土地清冊_匯入!$Q$6:$Q$1005,MATCH($A13,土地清冊_匯入!$A$6:$A$1005,0)),"")) | F13: =IF($A13="","",IFERROR(INDEX(土地清冊_匯入!$R$6:$R$1005,MATCH($A13,土地清冊_匯入!$A$6:$A$1005,0)),"")) | G13: =IF($A13="","",IFERROR(INDEX(土地清冊_匯入!$S$6:$S$1005,MATCH($A13,土地清冊_匯入!$A$6:$A$1005,0)),"")) | H13: =IF($A13="","",IFERROR(INDEX(土地清冊_匯入!$T$6:$T$1005,MATCH($A13,土地清冊_匯入!$A$6:$A$1005,0)),"")) | I13: =IF($A13="","",IFERROR(INDEX(土地清冊_匯入!$V$6:$V$1005,MATCH($A13,土地清冊_匯入!$A$6:$A$1005,0)),"")) | U13: =IF(A13="","",IF(OR(J13="",L13=""),"建議補聯絡紀錄","") )
C14: =IF($A14="","",IFERROR(INDEX(土地清冊_匯入!$B$6:$B$1005,MATCH($A14,土地清冊_匯入!$A$6:$A$1005,0)),"查無資料")) | D14: =IF($A14="","",IFERROR(INDEX(土地清冊_匯入!$P$6:$P$1005,MATCH($A14,土地清冊_匯入!$A$6:$A$1005,0)),"")) | E14: =IF($A14="","",IFERROR(INDEX(土地清冊_匯入!$Q$6:$Q$1005,MATCH($A14,土地清冊_匯入!$A$6:$A$1005,0)),"")) | F14: =IF($A14="","",IFERROR(INDEX(土地清冊_匯入!$R$6:$R$1005,MATCH($A14,土地清冊_匯入!$A$6:$A$1005,0)),"")) | G14: =IF($A14="","",IFERROR(INDEX(土地清冊_匯入!$S$6:$S$1005,MATCH($A14,土地清冊_匯入!$A$6:$A$1005,0)),"")) | H14: =IF($A14="","",IFERROR(INDEX(土地清冊_匯入!$T$6:$T$1005,MATCH($A14,土地清冊_匯入!$A$6:$A$1005,0)),"")) | I14: =IF($A14="","",IFERROR(INDEX(土地清冊_匯入!$V$6:$V$1005,MATCH($A14,土地清冊_匯入!$A$6:$A$1005,0)),"")) | U14: =IF(A14="","",IF(OR(J14="",L14=""),"建議補聯絡紀錄","") )
C15: =IF($A15="","",IFERROR(INDEX(土地清冊_匯入!$B$6:$B$1005,MATCH($A15,土地清冊_匯入!$A$6:$A$1005,0)),"查無資料")) | D15: =IF($A15="","",IFERROR(INDEX(土地清冊_匯入!$P$6:$P$1005,MATCH($A15,土地清冊_匯入!$A$6:$A$1005,0)),"")) | E15: =IF($A15="","",IFERROR(INDEX(土地清冊_匯入!$Q$6:$Q$1005,MATCH($A15,土地清冊_匯入!$A$6:$A$1005,0)),"")) | F15: =IF($A15="","",IFERROR(INDEX(土地清冊_匯入!$R$6:$R$1005,MATCH($A15,土地清冊_匯入!$A$6:$A$1005,0)),"")) | G15: =IF($A15="","",IFERROR(INDEX(土地清冊_匯入!$S$6:$S$1005,MATCH($A15,土地清冊_匯入!$A$6:$A$1005,0)),"")) | H15: =IF($A15="","",IFERROR(INDEX(土地清冊_匯入!$T$6:$T$1005,MATCH($A15,土地清冊_匯入!$A$6:$A$1005,0)),"")) | I15: =IF($A15="","",IFERROR(INDEX(土地清冊_匯入!$V$6:$V$1005,MATCH($A15,土地清冊_匯入!$A$6:$A$1005,0)),"")) | U15: =IF(A15="","",IF(OR(J15="",L15=""),"建議補聯絡紀錄","") )
C16: =IF($A16="","",IFERROR(INDEX(土地清冊_匯入!$B$6:$B$1005,MATCH($A16,土地清冊_匯入!$A$6:$A$1005,0)),"查無資料")) | D16: =IF($A16="","",IFERROR(INDEX(土地清冊_匯入!$P$6:$P$1005,MATCH($A16,土地清冊_匯入!$A$6:$A$1005,0)),"")) | E16: =IF($A16="","",IFERROR(INDEX(土地清冊_匯入!$Q$6:$Q$1005,MATCH($A16,土地清冊_匯入!$A$6:$A$1005,0)),"")) | F16: =IF($A16="","",IFERROR(INDEX(土地清冊_匯入!$R$6:$R$1005,MATCH($A16,土地清冊_匯入!$A$6:$A$1005,0)),"")) | G16: =IF($A16="","",IFERROR(INDEX(土地清冊_匯入!$S$6:$S$1005,MATCH($A16,土地清冊_匯入!$A$6:$A$1005,0)),"")) | H16: =IF($A16="","",IFERROR(INDEX(土地清冊_匯入!$T$6:$T$1005,MATCH($A16,土地清冊_匯入!$A$6:$A$1005,0)),"")) | I16: =IF($A16="","",IFERROR(INDEX(土地清冊_匯入!$V$6:$V$1005,MATCH($A16,土地清冊_匯入!$A$6:$A$1005,0)),"")) | U16: =IF(A16="","",IF(OR(J16="",L16=""),"建議補聯絡紀錄","") )
C17: =IF($A17="","",IFERROR(INDEX(土地清冊_匯入!$B$6:$B$1005,MATCH($A17,土地清冊_匯入!$A$6:$A$1005,0)),"查無資料")) | D17: =IF($A17="","",IFERROR(INDEX(土地清冊_匯入!$P$6:$P$1005,MATCH($A17,土地清冊_匯入!$A$6:$A$1005,0)),"")) | E17: =IF($A17="","",IFERROR(INDEX(土地清冊_匯入!$Q$6:$Q$1005,MATCH($A17,土地清冊_匯入!$A$6:$A$1005,0)),"")) | F17: =IF($A17="","",IFERROR(INDEX(土地清冊_匯入!$R$6:$R$1005,MATCH($A17,土地清冊_匯入!$A$6:$A$1005,0)),"")) | G17: =IF($A17="","",IFERROR(INDEX(土地清冊_匯入!$S$6:$S$1005,MATCH($A17,土地清冊_匯入!$A$6:$A$1005,0)),"")) | H17: =IF($A17="","",IFERROR(INDEX(土地清冊_匯入!$T$6:$T$1005,MATCH($A17,土地清冊_匯入!$A$6:$A$1005,0)),"")) | I17: =IF($A17="","",IFERROR(INDEX(土地清冊_匯入!$V$6:$V$1005,MATCH($A17,土地清冊_匯入!$A$6:$A$1005,0)),"")) | U17: =IF(A17="","",IF(OR(J17="",L17=""),"建議補聯絡紀錄","") )
... C1005: =IF($A1005="","",IFERROR(INDEX(土地清冊_匯入!$B$6:$B$1005,MATCH($A1005,土地清冊_匯入!$A$6:$A$1005,0)),"查無資料")) | D1005: =IF($A1005="","",IFERROR(INDEX(土地清冊_匯入!$P$6:$P$1005,MATCH($A1005,土地清冊_匯入!$A$6:$A$1005,0)),"")) | E1005: =IF($A1005="","",IFERROR(INDEX(土地清冊_匯入!$Q$6:$Q$1005,MATCH($A1005,土地清冊_匯入!$A$6:$A$1005,0)),"")) | F1005: =IF($A1005="","",IFERROR(INDEX(土地清冊_匯入!$R$6:$R$1005,MATCH($A1005,土地清冊_匯入!$A$6:$A$1005,0)),"")) | G1005: =IF($A1005="","",IFERROR(INDEX(土地清冊_匯入!$S$6:$S$1005,MATCH($A1005,土地清冊_匯入!$A$6:$A$1005,0)),"")) | H1005: =IF($A1005="","",IFERROR(INDEX(土地清冊_匯入!$T$6:$T$1005,MATCH($A1005,土地清冊_匯入!$A$6:$A$1005,0)),"")) | I1005: =IF($A1005="","",IFERROR(INDEX(土地清冊_匯入!$V$6:$V$1005,MATCH($A1005,土地清冊_匯入!$A$6:$A$1005,0)),"")) | U1005: =IF(A1005="","",IF(OR(J1005="",L1005=""),"建議補聯絡紀錄","") )

Sheet 分配條件_匯入
A1: 三策專案管理顧問有限公司
A2: Sanze Project Management Consulting Co., Ltd.
A3: 本模板為三策開發評估系統授權使用之標準清冊匯入格式。未經授權不得修改欄位結構、公式、驗證規則或轉作其他用途。
A4: 必填 | B4: 建議 | C4: 選填 | D4: 公式 | E4: 公式 | F4: 公式 | G4: 公式 | H4: 建議 | I4: 選填 | J4: 選填 | K4: 公式 | L4: 選填 | M4: 選填 | N4: 建議 | O4: 建議 | P4: 選填 | Q4: 建議 | R4: 建議 | S4: 建議 | T4: 選填 | U4: 公式
A5: 地主編號 | B5: 對應地號 | C5: 對應建號 | D5: 地主姓名 | E5: 土地持分面積坪 | F5: 建物面積㎡ | G5: 建物持分面積㎡ | H5: 分配模式 | I5: 每坪土地換建坪 | J5: 地主分回比例 | K5: 實施者分回比例 | L5: 分回坪數 | M5: 分回車位數 | N5: 是否含車位 | O5: 是否含店面 | P5: 找補金額 | Q5: 是否書面化 | R5: 條件狀態 | S5: 風險等級 | T5: 備註 | U5: 公式檢核提示
D6: =IF($A6="","",IFERROR(INDEX(土地清冊_匯入!$B$6:$B$1005,MATCH($A6,土地清冊_匯入!$A$6:$A$1005,0)),"查無資料")) | E6: =IF($A6="","",IFERROR(INDEX(土地清冊_匯入!$I$6:$I$1005,MATCH($A6,土地清冊_匯入!$A$6:$A$1005,0)),"")) | F6: =IF($A6="","",IFERROR(INDEX(建物清冊_匯入!$N$6:$N$1005,MATCH($A6,建物清冊_匯入!$A$6:$A$1005,0)),"")) | G6: =IF($A6="","",IFERROR(INDEX(建物清冊_匯入!$S$6:$S$1005,MATCH($A6,建物清冊_匯入!$A$6:$A$1005,0)),"")) | K6: =IF(J6="","",1-J6) | U6: =IF(A6="","",IF(H6="","建議填分配模式",""))
D7: =IF($A7="","",IFERROR(INDEX(土地清冊_匯入!$B$6:$B$1005,MATCH($A7,土地清冊_匯入!$A$6:$A$1005,0)),"查無資料")) | E7: =IF($A7="","",IFERROR(INDEX(土地清冊_匯入!$I$6:$I$1005,MATCH($A7,土地清冊_匯入!$A$6:$A$1005,0)),"")) | F7: =IF($A7="","",IFERROR(INDEX(建物清冊_匯入!$N$6:$N$1005,MATCH($A7,建物清冊_匯入!$A$6:$A$1005,0)),"")) | G7: =IF($A7="","",IFERROR(INDEX(建物清冊_匯入!$S$6:$S$1005,MATCH($A7,建物清冊_匯入!$A$6:$A$1005,0)),"")) | K7: =IF(J7="","",1-J7) | U7: =IF(A7="","",IF(H7="","建議填分配模式",""))
D8: =IF($A8="","",IFERROR(INDEX(土地清冊_匯入!$B$6:$B$1005,MATCH($A8,土地清冊_匯入!$A$6:$A$1005,0)),"查無資料")) | E8: =IF($A8="","",IFERROR(INDEX(土地清冊_匯入!$I$6:$I$1005,MATCH($A8,土地清冊_匯入!$A$6:$A$1005,0)),"")) | F8: =IF($A8="","",IFERROR(INDEX(建物清冊_匯入!$N$6:$N$1005,MATCH($A8,建物清冊_匯入!$A$6:$A$1005,0)),"")) | G8: =IF($A8="","",IFERROR(INDEX(建物清冊_匯入!$S$6:$S$1005,MATCH($A8,建物清冊_匯入!$A$6:$A$1005,0)),"")) | K8: =IF(J8="","",1-J8) | U8: =IF(A8="","",IF(H8="","建議填分配模式",""))
D9: =IF($A9="","",IFERROR(INDEX(土地清冊_匯入!$B$6:$B$1005,MATCH($A9,土地清冊_匯入!$A$6:$A$1005,0)),"查無資料")) | E9: =IF($A9="","",IFERROR(INDEX(土地清冊_匯入!$I$6:$I$1005,MATCH($A9,土地清冊_匯入!$A$6:$A$1005,0)),"")) | F9: =IF($A9="","",IFERROR(INDEX(建物清冊_匯入!$N$6:$N$1005,MATCH($A9,建物清冊_匯入!$A$6:$A$1005,0)),"")) | G9: =IF($A9="","",IFERROR(INDEX(建物清冊_匯入!$S$6:$S$1005,MATCH($A9,建物清冊_匯入!$A$6:$A$1005,0)),"")) | K9: =IF(J9="","",1-J9) | U9: =IF(A9="","",IF(H9="","建議填分配模式",""))
D10: =IF($A10="","",IFERROR(INDEX(土地清冊_匯入!$B$6:$B$1005,MATCH($A10,土地清冊_匯入!$A$6:$A$1005,0)),"查無資料")) | E10: =IF($A10="","",IFERROR(INDEX(土地清冊_匯入!$I$6:$I$1005,MATCH($A10,土地清冊_匯入!$A$6:$A$1005,0)),"")) | F10: =IF($A10="","",IFERROR(INDEX(建物清冊_匯入!$N$6:$N$1005,MATCH($A10,建物清冊_匯入!$A$6:$A$1005,0)),"")) | G10: =IF($A10="","",IFERROR(INDEX(建物清冊_匯入!$S$6:$S$1005,MATCH($A10,建物清冊_匯入!$A$6:$A$1005,0)),"")) | K10: =IF(J10="","",1-J10) | U10: =IF(A10="","",IF(H10="","建議填分配模式",""))
D11: =IF($A11="","",IFERROR(INDEX(土地清冊_匯入!$B$6:$B$1005,MATCH($A11,土地清冊_匯入!$A$6:$A$1005,0)),"查無資料")) | E11: =IF($A11="","",IFERROR(INDEX(土地清冊_匯入!$I$6:$I$1005,MATCH($A11,土地清冊_匯入!$A$6:$A$1005,0)),"")) | F11: =IF($A11="","",IFERROR(INDEX(建物清冊_匯入!$N$6:$N$1005,MATCH($A11,建物清冊_匯入!$A$6:$A$1005,0)),"")) | G11: =IF($A11="","",IFERROR(INDEX(建物清冊_匯入!$S$6:$S$1005,MATCH($A11,建物清冊_匯入!$A$6:$A$1005,0)),"")) | K11: =IF(J11="","",1-J11) | U11: =IF(A11="","",IF(H11="","建議填分配模式",""))
D12: =IF($A12="","",IFERROR(INDEX(土地清冊_匯入!$B$6:$B$1005,MATCH($A12,土地清冊_匯入!$A$6:$A$1005,0)),"查無資料")) | E12: =IF($A12="","",IFERROR(INDEX(土地清冊_匯入!$I$6:$I$1005,MATCH($A12,土地清冊_匯入!$A$6:$A$1005,0)),"")) | F12: =IF($A12="","",IFERROR(INDEX(建物清冊_匯入!$N$6:$N$1005,MATCH($A12,建物清冊_匯入!$A$6:$A$1005,0)),"")) | G12: =IF($A12="","",IFERROR(INDEX(建物清冊_匯入!$S$6:$S$1005,MATCH($A12,建物清冊_匯入!$A$6:$A$1005,0)),"")) | K12: =IF(J12="","",1-J12) | U12: =IF(A12="","",IF(H12="","建議填分配模式",""))
D13: =IF($A13="","",IFERROR(INDEX(土地清冊_匯入!$B$6:$B$1005,MATCH($A13,土地清冊_匯入!$A$6:$A$1005,0)),"查無資料")) | E13: =IF($A13="","",IFERROR(INDEX(土地清冊_匯入!$I$6:$I$1005,MATCH($A13,土地清冊_匯入!$A$6:$A$1005,0)),"")) | F13: =IF($A13="","",IFERROR(INDEX(建物清冊_匯入!$N$6:$N$1005,MATCH($A13,建物清冊_匯入!$A$6:$A$1005,0)),"")) | G13: =IF($A13="","",IFERROR(INDEX(建物清冊_匯入!$S$6:$S$1005,MATCH($A13,建物清冊_匯入!$A$6:$A$1005,0)),"")) | K13: =IF(J13="","",1-J13) | U13: =IF(A13="","",IF(H13="","建議填分配模式",""))
D14: =IF($A14="","",IFERROR(INDEX(土地清冊_匯入!$B$6:$B$1005,MATCH($A14,土地清冊_匯入!$A$6:$A$1005,0)),"查無資料")) | E14: =IF($A14="","",IFERROR(INDEX(土地清冊_匯入!$I$6:$I$1005,MATCH($A14,土地清冊_匯入!$A$6:$A$1005,0)),"")) | F14: =IF($A14="","",IFERROR(INDEX(建物清冊_匯入!$N$6:$N$1005,MATCH($A14,建物清冊_匯入!$A$6:$A$1005,0)),"")) | G14: =IF($A14="","",IFERROR(INDEX(建物清冊_匯入!$S$6:$S$1005,MATCH($A14,建物清冊_匯入!$A$6:$A$1005,0)),"")) | K14: =IF(J14="","",1-J14) | U14: =IF(A14="","",IF(H14="","建議填分配模式",""))
D15: =IF($A15="","",IFERROR(INDEX(土地清冊_匯入!$B$6:$B$1005,MATCH($A15,土地清冊_匯入!$A$6:$A$1005,0)),"查無資料")) | E15: =IF($A15="","",IFERROR(INDEX(土地清冊_匯入!$I$6:$I$1005,MATCH($A15,土地清冊_匯入!$A$6:$A$1005,0)),"")) | F15: =IF($A15="","",IFERROR(INDEX(建物清冊_匯入!$N$6:$N$1005,MATCH($A15,建物清冊_匯入!$A$6:$A$1005,0)),"")) | G15: =IF($A15="","",IFERROR(INDEX(建物清冊_匯入!$S$6:$S$1005,MATCH($A15,建物清冊_匯入!$A$6:$A$1005,0)),"")) | K15: =IF(J15="","",1-J15) | U15: =IF(A15="","",IF(H15="","建議填分配模式",""))
D16: =IF($A16="","",IFERROR(INDEX(土地清冊_匯入!$B$6:$B$1005,MATCH($A16,土地清冊_匯入!$A$6:$A$1005,0)),"查無資料")) | E16: =IF($A16="","",IFERROR(INDEX(土地清冊_匯入!$I$6:$I$1005,MATCH($A16,土地清冊_匯入!$A$6:$A$1005,0)),"")) | F16: =IF($A16="","",IFERROR(INDEX(建物清冊_匯入!$N$6:$N$1005,MATCH($A16,建物清冊_匯入!$A$6:$A$1005,0)),"")) | G16: =IF($A16="","",IFERROR(INDEX(建物清冊_匯入!$S$6:$S$1005,MATCH($A16,建物清冊_匯入!$A$6:$A$1005,0)),"")) | K16: =IF(J16="","",1-J16) | U16: =IF(A16="","",IF(H16="","建議填分配模式",""))
D17: =IF($A17="","",IFERROR(INDEX(土地清冊_匯入!$B$6:$B$1005,MATCH($A17,土地清冊_匯入!$A$6:$A$1005,0)),"查無資料")) | E17: =IF($A17="","",IFERROR(INDEX(土地清冊_匯入!$I$6:$I$1005,MATCH($A17,土地清冊_匯入!$A$6:$A$1005,0)),"")) | F17: =IF($A17="","",IFERROR(INDEX(建物清冊_匯入!$N$6:$N$1005,MATCH($A17,建物清冊_匯入!$A$6:$A$1005,0)),"")) | G17: =IF($A17="","",IFERROR(INDEX(建物清冊_匯入!$S$6:$S$1005,MATCH($A17,建物清冊_匯入!$A$6:$A$1005,0)),"")) | K17: =IF(J17="","",1-J17) | U17: =IF(A17="","",IF(H17="","建議填分配模式",""))
... D1005: =IF($A1005="","",IFERROR(INDEX(土地清冊_匯入!$B$6:$B$1005,MATCH($A1005,土地清冊_匯入!$A$6:$A$1005,0)),"查無資料")) | E1005: =IF($A1005="","",IFERROR(INDEX(土地清冊_匯入!$I$6:$I$1005,MATCH($A1005,土地清冊_匯入!$A$6:$A$1005,0)),"")) | F1005: =IF($A1005="","",IFERROR(INDEX(建物清冊_匯入!$N$6:$N$1005,MATCH($A1005,建物清冊_匯入!$A$6:$A$1005,0)),"")) | G1005: =IF($A1005="","",IFERROR(INDEX(建物清冊_匯入!$S$6:$S$1005,MATCH($A1005,建物清冊_匯入!$A$6:$A$1005,0)),"")) | K1005: =IF(J1005="","",1-J1005) | U1005: =IF(A1005="","",IF(H1005="","建議填分配模式",""))

Sheet 欄位字典
A1: 工作表 | B1: 欄位名稱 | C1: 填寫屬性 | D1: 型態 | E1: 是否公式 | F1: 下拉來源 | G1: 說明
A2: 土地清冊_匯入 | B2: 地主編號 | C2: 必填 | D2: text | E2: 否 | G2: 跨表連動 key，建議格式 O001。
A3: 土地清冊_匯入 | B3: 地主姓名 | C3: 必填 | D3: text | E3: 否
A4: 土地清冊_匯入 | B4: 縣市 | C4: 必填 | D4: text | E4: 否
A5: 土地清冊_匯入 | B5: 行政區 | C5: 必填 | D5: text | E5: 否
A6: 土地清冊_匯入 | B6: 段別 | C6: 必填 | D6: text | E6: 否
A7: 土地清冊_匯入 | B7: 小段 | C7: 選填 | D7: text | E7: 否 | G7: 僅現況地號明確有小段時填寫；重劃前小段不得填入此欄。
A8: 土地清冊_匯入 | B8: 地號 | C8: 必填 | D8: text | E8: 否
A9: 土地清冊_匯入 | B9: 土地面積㎡ | C9: 必填 | D9: decimal | E9: 否
A10: 土地清冊_匯入 | B10: 土地面積坪 | C10: 公式 | D10: formula | E10: 是
A11: 土地清冊_匯入 | B11: 持分分子 | C11: 必填 | D11: decimal | E11: 否
A12: 土地清冊_匯入 | B12: 持分分母 | C12: 必填 | D12: integer | E12: 否
A13: 土地清冊_匯入 | B13: 持分比例 | C13: 公式 | D13: formula | E13: 是
A14: 土地清冊_匯入 | B14: 持分面積坪 | C14: 公式 | D14: formula | E14: 是
A15: 土地清冊_匯入 | B15: 使用分區 | C15: 建議 | D15: dropdown | E15: 否 | F15: 使用分區
A16: 土地清冊_匯入 | B16: 公告現值（元/㎡） | C16: 選填 | D16: decimal | E16: 否
A17: 土地清冊_匯入 | B17: 公告地價 | C17: 選填 | D17: decimal | E17: 否
A18: 土地清冊_匯入 | B18: 抵押設定 | C18: 建議 | D18: dropdown | E18: 否 | F18: 是否類
A19: 土地清冊_匯入 | B19: 查封限制 | C19: 建議 | D19: dropdown | E19: 否 | F19: 是否類
A20: 土地清冊_匯入 | B20: 繼承狀態 | C20: 建議 | D20: dropdown | E20: 否 | F20: 繼承狀態
A21: 土地清冊_匯入 | B21: 聯絡方式 | C21: 選填 | D21: text | E21: 否
A22: 土地清冊_匯入 | B22: 聯絡狀態 | C22: 建議 | D22: dropdown | E22: 否 | F22: 聯絡狀態
A23: 土地清冊_匯入 | B23: 同意狀態 | C23: 建議 | D23: dropdown | E23: 否 | F23: 同意狀態
A24: 土地清冊_匯入 | B24: 簽約狀態 | C24: 建議 | D24: dropdown | E24: 否 | F24: 簽約狀態
A25: 土地清冊_匯入 | B25: 整合負責人 | C25: 選填 | D25: text | E25: 否
A26: 土地清冊_匯入 | B26: 風險等級 | C26: 建議 | D26: dropdown | E26: 否 | F26: 風險等級
A27: 土地清冊_匯入 | B27: 特殊備註 | C27: 選填 | D27: text | E27: 否
A28: 土地清冊_匯入 | B28: 公式檢核提示 | C28: 公式 | D28: formula | E28: 是
A29: 土地清冊_匯入 | B29: 地主地號查找鍵 | C29: 公式 | D29: formula | E29: 是
A30: 建物清冊_匯入 | B30: 建物編號 | C30: 必填 | D30: text | E30: 否 | G30: 建物清冊內部編號。
A31: 建物清冊_匯入 | B31: 所有人姓名 | C31: 必填 | D31: text | E31: 否
A32: 建物清冊_匯入 | B32: 縣市 | C32: 必填 | D32: text | E32: 否
A33: 建物清冊_匯入 | B33: 行政區 | C33: 必填 | D33: text | E33: 否
A34: 建物清冊_匯入 | B34: 段別 | C34: 必填 | D34: text | E34: 否
A35: 建物清冊_匯入 | B35: 小段 | C35: 選填 | D35: text | E35: 否 | G35: 僅現況建物標示明確有小段時填寫。
A36: 建物清冊_匯入 | B36: 地號 | C36: 建議 | D36: text | E36: 否
A37: 建物清冊_匯入 | B37: 建號 | C37: 必填 | D37: text | E37: 否
A38: 建物清冊_匯入 | B38: 聯絡方式 | C38: 選填 | D38: text | E38: 否
A39: 建物清冊_匯入 | B39: 聯絡狀態 | C39: 建議 | D39: dropdown | E39: 否 | F39: 聯絡狀態
A40: 建物清冊_匯入 | B40: 同意狀態 | C40: 建議 | D40: dropdown | E40: 否 | F40: 同意狀態
...

Sheet 下拉選單
A1: 使用分區 | B1: 同意狀態 | C1: 聯絡狀態 | D1: 簽約狀態 | E1: 是否類 | F1: 風險等級 | G1: 分配模式 | H1: 用途 | I1: 繼承狀態 | J1: 聯絡方式 | K1: 聯絡結果 | L1: 下一步處理 | M1: 條件狀態 | N1: 建物型態
A2: 住宅區 | B2: 未接觸 | C2: 未聯絡 | D2: 未簽 | E2: 是 | F2: 低 | G2: 坪換坪 | H2: 住宅 | I2: 無 | J2: 電話 | K2: 已說明 | L2: 再次電話 | M2: 草案 | N2: 公寓
A3: 商業區 | B3: 已接觸 | C3: 已聯絡 | D3: 洽談中 | E3: 否 | F3: 中 | G3: 比例分配 | H3: 店鋪 | I3: 辦理中 | J3: LINE | K3: 待回覆 | L3: 安排面談 | M3: 洽談中 | N3: 透天
A4: 工業區 | B4: 說明中 | C4: 無回應 | D4: 已簽 | E4: 不明 | F4: 高 | G4: 權利變換預估 | H4: 辦公 | I4: 已完成 | J4: 簡訊 | K4: 無回應 | L4: 寄送資料 | M4: 已確認 | N4: 華廈
A5: 住商混合 | B5: 同意 | C5: 已面談 | D5: 拒簽 | F5: 重大 | G5: 自訂條件 | H5: 工業 | I5: 有爭議 | J5: Email | K5: 同意 | L5: 補件確認 | M5: 待修正 | N5: 大樓
H6: 其他 | J6: 面談 | K6: 拒絕 | L6: 暫緩 | N6: 其他
J7: 其他 | K7: 需補資料
